Workbook
Name IQ_CH: 110000
Name IQ_CQ: 5000
Name IQ_CY: 10000
Name IQ_DAILY: 500000
Name IQ_FH: 100000
Name IQ_FQ: 500
Name IQ_FY: 1000
Name IQ_LTM: 2000
Name IQ_MONTH: 15000
Name IQ_NTM: 6000
Name IQ_WEEK: 50000
Name IQ_YTD: 3000

Sheet Quarterly
A1: ILMN key numbers: quarterly (last four reported quarters and 2026-27 consensus)
A2: $M unless noted. A = reported, E = Bloomberg consensus (10 Oct 2026). Non-GAAP unless noted. 2024 comparisons on a Core Illumina (ex-GRAIL) basis. n/a = not disclosed / no consensus.
A4: Metric | B4: Q3'25 | C4: Q4'25 | D4: Q1'26 | E4: Q2'26 | F4: Q3'26E | G4: Q4'26E | H4: Q1'27E | I4: Q2'27E | J4: Q3'27E | K4: Q4'27E
A5: Revenue
A6: Consolidated revenue ($M) | B6: =Data!I4 -> 1084 | C6: =Data!J4 -> 1159 | D6: =Data!K4 -> 1091 | E6: =Data!L4 -> 1159 | F6: =Data!M4 -> 1154.2 | G6: =Data!N4 -> 1219.8 | H6: =Data!O4 -> 1159.6 | I6: =Data!P4 -> 1217.8 | ... K6: =Data!R4 -> 1292.3
A7: y/y | B7: =Data!I5 -> 0.0037037037 | C7: =Data!J5 -> 0.049818841 | D7: =Data!K5 -> 0.04803074 | E7: =Data!L5 -> 0.094428706 | F7: =Data!M5 -> 0.064760148 | G7: =Data!N5 -> 0.052459016 | H7: =Data!O5 -> 0.062878093 | I7: =Data!P5 -> 0.050733391 | ... K7: =Data!R5 -> 0.059435973
A8: q/q | B8: =Data!I6 -> 0.023607177 | C8: =Data!J6 -> 0.069188192 | D8: =Data!K6 -> -0.058671268 | E8: =Data!L6 -> 0.062328139 | F8: =Data!M6 -> -0.0041415013 | G8: =Data!N6 -> 0.056835904 | H8: =Data!O6 -> -0.049352353 | I8: =Data!P6 -> 0.050189721 | ... K8: =Data!R6 -> 0.051334201
A9: 2-yr stack | B9: =Data!I7 -> -0.016296296 | C9: =Data!J7 -> 0.059818841 | D9: =Data!K7 -> 0.033826194 | E9: =Data!L7 -> 0.064208926 | F9: =Data!M7 -> 0.068463851 | G9: =Data!N7 -> 0.10227786 | H9: =Data!O7 -> 0.11090883 | I9: =Data!P7 -> 0.1451621 | ... K9: =Data!R7 -> 0.11189499
A10: Revenue ex-China ($M) | B10: =Data!I9 -> 1032 | C10: =Data!J9 -> 1104 | D10: =Data!K9 -> 1039 | E10: =Data!L9 -> 1103 | F10: =Data!M9 -> 1103.4 | G10: =Data!N9 -> 1167.9 | H10: =Data!O9 -> 1115 | I10: =Data!P9 -> 1170.8 | ... K10: =Data!R9 -> 1243.4
A11: y/y | B11: =Data!I10 -> 0.026865672 | C11: =Data!J10 -> 0.078125 | D11: =Data!K10 -> 0.072239422 | E11: =Data!L10 -> 0.10742972 | F11: =Data!M10 -> 0.069186047 | G11: =Data!N10 -> 0.057880435 | H11: =Data!O10 -> 0.073147257 | I11: =Data!P10 -> 0.061468722 | ... K11: =Data!R10 -> 0.064645946
A12: q/q | B12: =Data!I11 -> 0.036144578 | C12: =Data!J11 -> 0.069767442 | D12: =Data!K11 -> -0.058876812 | E12: =Data!L11 -> 0.06159769 | F12: =Data!M11 -> 0.00036264733 | G12: =Data!N11 -> 0.058455682 | H12: =Data!O11 -> -0.045294974 | I12: =Data!P11 -> 0.050044843 | ... K12: =Data!R11 -> 0.051323243
A13: 2-yr stack | B13: =Data!I12 -> n/a | C13: =Data!J12 -> n/a | D13: =Data!K12 -> 0.063036968 | E13: =Data!L12 -> 0.086780751 | F13: =Data!M12 -> 0.096051718 | G13: =Data!N12 -> 0.13600543 | H13: =Data!O12 -> 0.14538668 | I13: =Data!P12 -> 0.16889844 | ... K13: =Data!R12 -> 0.12252638
A14: Instrument placements
A15: NovaSeq X placements (units; lower bounds) | B15: =Data!I14 -> 55 | C15: =Data!J14 -> 100 | D15: =Data!K14 -> 83 | E15: =Data!L14 -> 95 | F15: =Data!M14 -> n/a | G15: =Data!N14 -> n/a | H15: =Data!O14 -> n/a | I15: =Data!P14 -> n/a | ... K15: =Data!R14 -> n/a
A16: y/y | B16: =Data!I15 -> -0.051724138 | C16: =Data!J15 -> 0.098901099 | D16: =Data!K15 -> 0.38333333 | E16: =Data!L15 -> 0.9 | F16: =Data!M15 -> n/a | G16: =Data!N15 -> n/a | H16: =Data!O15 -> n/a | I16: =Data!P15 -> n/a | ... K16: =Data!R15 -> n/a
A17: q/q | B17: =Data!I16 -> 0.1 | C17: =Data!J16 -> 0.81818182 | D17: =Data!K16 -> -0.17 | E17: =Data!L16 -> 0.14457831 | F17: =Data!M16 -> n/a | G17: =Data!N16 -> n/a | H17: =Data!O16 -> n/a | I17: =Data!P16 -> n/a | ... K17: =Data!R16 -> n/a
A18: 2-yr stack | B18: =Data!I17 -> -0.45378599 | C18: =Data!J17 -> 0.25079983 | D18: =Data!K17 -> 0.47424242 | E18: =Data!L17 -> 0.70645161 | F18: =Data!M17 -> n/a | G18: =Data!N17 -> n/a | H18: =Data!O17 -> n/a | I18: =Data!P17 -> n/a | ... K18: =Data!R17 -> n/a
A19: Clinical share of X placements | B19: =Data!I160 -> >50% | C19: =Data!J160 -> >60% | D19: =Data!K160 -> >60% | E19: =Data!L160 -> ~60-70% | F19: =Data!M160 -> n/a | G19: =Data!N160 -> n/a | H19: =Data!O160 -> n/a | I19: =Data!P160 -> n/a | ... K19: =Data!R160 -> n/a
A20: Instruments
A21: Instruments revenue ($M) | B21: =Data!I19 -> 111 | C21: =Data!J19 -> 158 | D21: =Data!K19 -> 120 | E21: =Data!L19 -> 130 | F21: =Data!M19 -> 115.2 | G21: =Data!N19 -> 131.5 | H21: =Data!O19 -> 111.1 | I21: =Data!P19 -> 114 | ... K21: =Data!R19 -> 126.8
A22: y/y | B22: =Data!I20 -> 0.037383178 | C22: =Data!J20 -> -0.0062893082 | D22: =Data!K20 -> 0.071428571 | E22: =Data!L20 -> 0.28712871 | F22: =Data!M20 -> 0.037837838 | G22: =Data!N20 -> -0.16772152 | H22: =Data!O20 -> -0.074166667 | I22: =Data!P20 -> -0.12307692 | ... K22: =Data!R20 -> -0.035741445
A23: q/q | B23: =Data!I21 -> 0.099009901 | C23: =Data!J21 -> 0.42342342 | D23: =Data!K21 -> -0.24050633 | E23: =Data!L21 -> 0.083333333 | F23: =Data!M21 -> -0.11384615 | G23: =Data!N21 -> 0.14149306 | H23: =Data!O21 -> -0.15513308 | I23: =Data!P21 -> 0.02610261 | ... K23: =Data!R21 -> 0.13620072
A24: 2-yr stack | B24: =Data!I22 -> -0.37470473 | C24: =Data!J22 -> -0.0541935 | D24: =Data!K22 -> 0.053884712 | E24: =Data!L22 -> 0.12879538 | F24: =Data!M22 -> 0.075221015 | G24: =Data!N22 -> -0.17401083 | H24: =Data!O22 -> -0.0027380952 | I24: =Data!P22 -> 0.16405179 | ... K24: =Data!R22 -> -0.20346296
A25: Sequencing instruments ex-China ($M) | B25: =Data!I24 -> 104 | C25: =Data!J24 -> 150 | D25: =Data!K24 -> 114 | E25: =Data!L24 -> 122 | F25: =Data!M24 -> n/a | G25: =Data!N24 -> n/a | H25: =Data!O24 -> n/a | I25: =Data!P24 -> n/a | ... K25: =Data!R24 -> n/a
A26: y/y | B26: =Data!I25 -> 0.06122449 | C26: =Data!J25 -> 0.041666667 | D26: =Data!K25 -> 0.10679612 | E26: =Data!L25 -> 0.32608696 | F26: =Data!M25 -> n/a | G26: =Data!N25 -> n/a | H26: =Data!O25 -> n/a | I26: =Data!P25 -> n/a | ... K26: =Data!R25 -> n/a
A27: q/q | B27: =Data!I26 -> 0.13043478 | C27: =Data!J26 -> 0.44230769 | D27: =Data!K26 -> -0.24 | E27: =Data!L26 -> 0.070175439 | F27: =Data!M26 -> n/a | G27: =Data!N26 -> n/a | H27: =Data!O26 -> n/a | I27: =Data!P26 -> n/a | ... K27: =Data!R26 -> n/a
A28: 2-yr stack | B28: =Data!I27 -> n/a | C28: =Data!J27 -> n/a | D28: =Data!K27 -> 0.13679612 | E28: =Data!L27 -> 0.15491579 | F28: =Data!M27 -> n/a | G28: =Data!N27 -> n/a | H28: =Data!O27 -> n/a | I28: =Data!P27 -> n/a | ... K28: =Data!R27 -> n/a
A29: Consumables
A30: Consumables revenue ($M) | B30: =Data!I29 -> 816 | C30: =Data!J29 -> 832 | D30: =Data!K29 -> 797 | E30: =Data!L29 -> 852 | F30: =Data!M29 -> 861 | G30: =Data!N29 -> 894.2 | H30: =Data!O29 -> 862.8 | I30: =Data!P29 -> 914.1 | ... K30: =Data!R29 -> 966.6
A31: y/y | B31: =Data!I30 -> 0.011152416 | C31: =Data!J30 -> 0.068035944 | D31: =Data!K30 -> 0.037760417 | E31: =Data!L30 -> 0.050554871 | F31: =Data!M30 -> 0.055147059 | G31: =Data!N30 -> 0.074759615 | H31: =Data!O30 -> 0.082559598 | I31: =Data!P30 -> 0.072887324 | ... K31: =Data!R30 -> 0.080966227
A32: q/q | B32: =Data!I31 -> 0.0061652281 | C32: =Data!J31 -> 0.019607843 | D32: =Data!K31 -> -0.042067308 | E32: =Data!L31 -> 0.069008783 | F32: =Data!M31 -> 0.01056338 | G32: =Data!N31 -> 0.038559814 | H32: =Data!O31 -> -0.035115187 | I32: =Data!P31 -> 0.05945758 | ... K32: =Data!R31 -> 0.037681159
A33: 2-yr stack | B33: =Data!I32 -> 0.064677221 | C33: =Data!J32 -> 0.098459224 | D33: =Data!K32 -> 0.037760417 | E33: =Data!L32 -> 0.045646895 | F33: =Data!M32 -> 0.066299475 | G33: =Data!N32 -> 0.14279556 | H33: =Data!O32 -> 0.12032002 | I33: =Data!P32 -> 0.12344219 | ... K33: =Data!R32 -> 0.15572584
A34: Sequencing consumables ($M) | B34: =Data!I34 -> 747 | C34: =Data!J34 -> 755 | D34: =Data!K34 -> 726 | E34: =Data!L34 -> 775 | F34: =Data!M34 -> 789.2 | G34: =Data!N34 -> 814.9 | H34: =Data!O34 -> 792.1 | I34: =Data!P34 -> 838.9 | ... K34: =Data!R34 -> 888.1
A35: y/y | B35: =Data!I35 -> 0.008097166 | C35: =Data!J35 -> 0.081661891 | D35: =Data!K35 -> 0.043103448 | E35: =Data!L35 -> 0.047297297 | F35: =Data!M35 -> 0.056492637 | G35: =Data!N35 -> 0.079337748 | H35: =Data!O35 -> 0.091046832 | I35: =Data!P35 -> 0.082451613 | ... K35: =Data!R35 -> 0.089826973
A36: q/q | B36: =Data!I36 -> 0.0094594595 | C36: =Data!J36 -> 0.010709505 | D36: =Data!K36 -> -0.038410596 | E36: =Data!L36 -> 0.067493113 | F36: =Data!M36 -> 0.018322581 | G36: =Data!N36 -> 0.032564622 | H36: =Data!O36 -> -0.027978893 | I36: =Data!P36 -> 0.059083449 | ... K36: =Data!R36 -> 0.032914631
A37: 2-yr stack | B37: =Data!I37 -> 0.083568864 | C37: =Data!J37 -> 0.1051223 | D37: =Data!K37 -> 0.041668728 | E37: =Data!L37 -> 0.051367854 | F37: =Data!M37 -> 0.064589803 | G37: =Data!N37 -> 0.16099964 | H37: =Data!O37 -> 0.13415028 | I37: =Data!P37 -> 0.12974891 | ... K37: =Data!R37 -> 0.16916472
A38: Sequencing consumables ex-China ($M) | B38: =Data!I39 -> 707 | C38: =Data!J39 -> 713 | D38: =Data!K39 -> 687 | E38: =Data!L39 -> 734 | F38: =Data!M39 -> n/a | G38: =Data!N39 -> n/a | H38: =Data!O39 -> n/a | I38: =Data!P39 -> n/a | ... K38: =Data!R39 -> n/a
A39: y/y | B39: =Data!I40 -> 0.033625731 | C39: =Data!J40 -> 0.1140625 | D39: =Data!K40 -> 0.0734375 | E39: =Data!L40 -> 0.063768116 | F39: =Data!M40 -> n/a | G39: =Data!N40 -> n/a | H39: =Data!O40 -> n/a | I39: =Data!P40 -> n/a | ... K39: =Data!R40 -> n/a
A40: q/q | B40: =Data!I41 -> 0.024637681 | C40: =Data!J41 -> 0.0084865629 | D40: =Data!K41 -> -0.036465638 | E40: =Data!L41 -> 0.068413392 | F40: =Data!M41 -> n/a | G40: =Data!N41 -> n/a | H40: =Data!O41 -> n/a | I40: =Data!P41 -> n/a | ... K40: =Data!R41 -> n/a
A41: 2-yr stack | B41: =Data!I42 -> 0.12362573 | C41: =Data!J42 -> 0.1340625 | D41: =Data!K42 -> 0.070322235 | E41: =Data!L42 -> 0.07996841 | F41: =Data!M42 -> n/a | G41: =Data!N42 -> n/a | H41: =Data!O42 -> n/a | I41: =Data!P42 -> n/a | ... K41: =Data!R42 -> n/a
...

Sheet Annual
A1: ILMN key numbers: annual (FY25 reported, FY26-FY30 consensus)
A2: $M unless noted. A = reported, E = Bloomberg consensus (10 Oct 2026). Non-GAAP unless noted. 2024 comparisons on a Core Illumina (ex-GRAIL) basis. n/a = not disclosed / no consensus.
A4: Metric | B4: FY25 | C4: FY26E | D4: FY27E | E4: FY28E | F4: FY29E | G4: FY30E
A5: Revenue
A6: Consolidated revenue ($M) | B6: =Data!W4 -> 4343 | C6: =Data!X4 -> 4624.8 | D6: =Data!Y4 -> 4918.3 | E6: =Data!Z4 -> 5262.8 | F6: =Data!AA4 -> 5649.7 | G6: =Data!AB4 -> 6087.9
A7: y/y | B7: =Data!W5 -> 0.0025392428 | C7: =Data!X5 -> 0.064886023 | D7: =Data!Y5 -> 0.063462204 | E7: =Data!Z5 -> 0.070044528 | F7: =Data!AA5 -> 0.073515999 | G7: =Data!AB5 -> 0.07756164
A8: 2-yr stack | B8: =Data!W7 -> -0.02134539 | C8: =Data!X7 -> 0.067425266 | D8: =Data!Y7 -> 0.12834823 | E8: =Data!Z7 -> 0.13350673 | F8: =Data!AA7 -> 0.14356053 | G8: =Data!AB7 -> 0.15107764
A9: Revenue ex-China ($M) | B9: =Data!W9 -> 4100 | C9: =Data!X9 -> 4414.1 | D9: =Data!Y9 -> 4729 | E9: =Data!Z9 -> 5075.7 | F9: =Data!AA9 -> 5419.8 | G9: =Data!AB9 -> 5881
A10: y/y | B10: =Data!W10 -> 0.01888668 | C10: =Data!X10 -> 0.076609756 | D10: =Data!Y10 -> 0.071339571 | E10: =Data!Z10 -> 0.073313597 | F10: =Data!AA10 -> 0.067793605 | G10: =Data!AB10 -> 0.085095391
A11: 2-yr stack | B11: =Data!W12 -> 0.011486581 | C11: =Data!X12 -> 0.095496436 | D11: =Data!Y12 -> 0.14794933 | E11: =Data!Z12 -> 0.14465317 | F11: =Data!AA12 -> 0.1411072 | G11: =Data!AB12 -> 0.152889
A12: Instrument placements
A13: NovaSeq X placements (units; lower bounds) | B13: =Data!W14 -> 265 | C13: =Data!X14 -> n/a | D13: =Data!Y14 -> n/a | E13: =Data!Z14 -> n/a | F13: =Data!AA14 -> n/a | G13: =Data!AB14 -> n/a
A14: y/y | B14: =Data!W15 -> -0.0037593985 | C14: =Data!X15 -> n/a | D14: =Data!Y15 -> n/a | E14: =Data!Z15 -> n/a | F14: =Data!AA15 -> n/a | G14: =Data!AB15 -> n/a
A15: 2-yr stack | B15: =Data!W17 -> -0.24807758 | C15: =Data!X17 -> n/a | D15: =Data!Y17 -> n/a | E15: =Data!Z17 -> n/a | F15: =Data!AA17 -> n/a | G15: =Data!AB17 -> n/a
A16: Clinical share of X placements | B16: =Data!W160 -> n/a | C16: =Data!X160 -> n/a | D16: =Data!Y160 -> n/a | E16: =Data!Z160 -> n/a | F16: =Data!AA160 -> n/a | G16: =Data!AB160 -> n/a
A17: Instruments
A18: Instruments revenue ($M) | B18: =Data!W19 -> 482 | C18: =Data!X19 -> 500.4 | D18: =Data!Y19 -> 469.7 | E18: =Data!Z19 -> 468.5 | F18: =Data!AA19 -> 464.6 | G18: =Data!AB19 -> 482.5
A19: y/y | B19: =Data!W20 -> -0.037924152 | C19: =Data!X20 -> 0.038174274 | D19: =Data!Y20 -> -0.061350919 | E19: =Data!Z20 -> -0.0025548222 | F19: =Data!AA20 -> -0.0083244397 | G19: =Data!AB20 -> 0.038527766
A20: 2-yr stack | B20: =Data!W22 -> -0.32627642 | C20: =Data!X22 -> 0.00025012216 | D20: =Data!Y22 -> -0.023176645 | E20: =Data!Z22 -> -0.063905741 | F20: =Data!AA22 -> -0.010879262 | G20: =Data!AB22 -> 0.030203326
A21: Sequencing instruments ex-China ($M) | B21: =Data!W24 -> 449 | C21: =Data!X24 -> n/a | D21: =Data!Y24 -> n/a | E21: =Data!Z24 -> n/a | F21: =Data!AA24 -> n/a | G21: =Data!AB24 -> n/a
A22: y/y | B22: =Data!W25 -> -0.0088300221 | C22: =Data!X25 -> n/a | D22: =Data!Y25 -> n/a | E22: =Data!Z25 -> n/a | F22: =Data!AA25 -> n/a | G22: =Data!AB25 -> n/a
A23: 2-yr stack | B23: =Data!W27 -> n/a | C23: =Data!X27 -> n/a | D23: =Data!Y27 -> n/a | E23: =Data!Z27 -> n/a | F23: =Data!AA27 -> n/a | G23: =Data!AB27 -> n/a
A24: Consumables
A25: Consumables revenue ($M) | B25: =Data!W29 -> 3227 | C25: =Data!X29 -> 3402.1 | D25: =Data!Y29 -> 3668.6 | E25: =Data!Z29 -> 3963.8 | F25: =Data!AA29 -> 4341.2 | G25: =Data!AB29 -> 4791.6
A26: y/y | B26: =Data!W30 -> 0.018302304 | C26: =Data!X30 -> 0.054260923 | D26: =Data!Y30 -> 0.07833397 | E26: =Data!Z30 -> 0.080466663 | F26: =Data!AA30 -> 0.095211666 | G26: =Data!AB30 -> 0.10375012
A27: 2-yr stack | B27: =Data!W32 -> 0.046197211 | C27: =Data!X32 -> 0.072563227 | D27: =Data!Y32 -> 0.13259489 | E27: =Data!Z32 -> 0.15880063 | F27: =Data!AA32 -> 0.17567833 | G27: =Data!AB32 -> 0.19896178
A28: Sequencing consumables ($M) | B28: =Data!W34 -> 2939 | C28: =Data!X34 -> 3104.4 | D28: =Data!Y34 -> 3378.4 | E28: =Data!Z34 -> 3694.2 | F28: =Data!AA34 -> 4034 | G28: =Data!AB34 -> 4478.8
A29: y/y | B29: =Data!W35 -> 0.023328691 | C29: =Data!X35 -> 0.056277645 | D29: =Data!Y35 -> 0.088261822 | E29: =Data!Z35 -> 0.093476202 | F29: =Data!AA35 -> 0.091982026 | G29: =Data!AB35 -> 0.11026277
A30: 2-yr stack | B30: =Data!W37 -> 0.052719372 | C30: =Data!X37 -> 0.079606336 | D30: =Data!Y37 -> 0.14453947 | E30: =Data!Z37 -> 0.18173802 | F30: =Data!AA37 -> 0.18545823 | G30: =Data!AB37 -> 0.20224479
A31: Sequencing consumables ex-China ($M) | B31: =Data!W39 -> 2750 | C31: =Data!X39 -> n/a | D31: =Data!Y39 -> n/a | E31: =Data!Z39 -> n/a | F31: =Data!AA39 -> n/a | G31: =Data!AB39 -> n/a
A32: y/y | B32: =Data!W40 -> 0.039697543 | C32: =Data!X40 -> n/a | D32: =Data!Y40 -> n/a | E32: =Data!Z40 -> n/a | F32: =Data!AA40 -> n/a | G32: =Data!AB40 -> n/a
A33: 2-yr stack | B33: =Data!W42 -> 0.079697543 | C33: =Data!X42 -> n/a | D33: =Data!Y42 -> n/a | E33: =Data!Z42 -> n/a | F33: =Data!AA42 -> n/a | G33: =Data!AB42 -> n/a
A34: Clinical vs research (ex-China sequencing consumables)
A35: Clinical, y/y | B35: =Data!W44 -> 0.12 | C35: =Data!X44 -> 0.15 | D35: =Data!Y44 -> n/a | E35: =Data!Z44 -> n/a | F35: =Data!AA44 -> n/a | G35: =Data!AB44 -> n/a
A36: 2-yr stack | B36: =Data!W45 -> 0.2 | C36: =Data!X45 -> 0.27 | D36: =Data!Y45 -> n/a | E36: =Data!Z45 -> n/a | F36: =Data!AA45 -> n/a | G36: =Data!AB45 -> n/a
A37: Research & applied, y/y | B37: =Data!W47 -> -0.07 | C37: =Data!X47 -> -0.075 | D37: =Data!Y47 -> n/a | E37: =Data!Z47 -> n/a | F37: =Data!AA47 -> n/a | G37: =Data!AB47 -> n/a
A38: 2-yr stack | B38: =Data!W48 -> -0.09 | C38: =Data!X48 -> -0.145 | D38: =Data!Y48 -> n/a | E38: =Data!Z48 -> n/a | F38: =Data!AA48 -> n/a | G38: =Data!AB48 -> n/a
A39: Volume and implied pricing
A40: Sequencing volume (Gb), y/y | B40: =Data!W158 -> >30% | C40: =Data!X158 -> n/a | D40: =Data!Y158 -> n/a | E40: =Data!Z158 -> n/a | F40: =Data!AA158 -> n/a | G40: =Data!AB158 -> n/a
A41: 2-yr stack | B41: =Data!W159 -> >60% | C41: =Data!X159 -> n/a | D41: =Data!Y159 -> n/a | E41: =Data!Z159 -> n/a | F41: =Data!AA159 -> n/a | G41: =Data!AB159 -> n/a
...

Sheet Addendum
A1: A. GAAP to non-GAAP adjustments ($M)
A2: Stock-based compensation is NOT added back: it stays inside non-GAAP costs (only its book-vs-tax difference is adjusted in the tax line). Source: ILMN earnings decks' reconciliation tables.
A3: Item | B3: Q3'25 | C3: Q4'25 | D3: FY25 | E3: Q1'26 | F3: Q2'26
A4: GAAP gross profit | B4: 733 | C4: 759 | D4: 2870 | E4: 721 | F4: 770
A5: + Amortization of acquired intangibles (COGS) | B5: 16 | C5: 16 | D5: 66 | E5: 17 | F5: 18
A6: + Other acquisition-related (COGS; incl. SomaLogic inventory step-up) | B6: 0 | C6: 0 | D6: 0 | E6: 6 | F6: 2
A7: + Transformational initiatives (COGS) | B7: 1 | C7: 2 | D7: 5 | E7: 0 | F7: 0
A8: + Intangible impairment (COGS, Q2'25) | B8: 0 | C8: 0 | D8: 23 | E8: 0 | F8: 0
A9: NON-GAAP GROSS PROFIT | B9: 750 | C9: 777 | D9: 2964 | E9: 744 | F9: 790
A10: GAAP operating income | B10: 227 | C10: 202 | D10: 807 | E10: 209 | F10: 245
A11: + Cost-of-revenue items (above) | B11: 17 | C11: 18 | D11: 94 | E11: 23 | F11: 20
A12: + R&D items | B12: 1 | C12: 1 | D12: 17 | E12: 1 | F12: 0
A13: + SG&A items (acquisition, transformation, other) | B13: 20 | C13: 46 | D13: 76 | E13: 7 | F13: -5
A14: + Legal contingency and settlement | B14: 0 | C14: 8 | D14: 10 | E14: 0 | F14: 0
A15: NON-GAAP OPERATING INCOME | B15: 265 | C15: 275 | D15: 1004 | E15: 239 | F15: 260
... A19: NON-GAAP NET INCOME | B19: 206 | C19: 208 | D19: 756 | E19: 178 | F19: 200
A21: What sits inside the buckets:
A22: - Acquisition-related: intangible amortization ($16-18M a quarter); SomaLogic/GRAIL legal and deal costs; contingent-consideration fair-value changes (gains of $16M in both Q1'26 and Q2'26 reduce the add-back); SomaLogic inventory step-up ($6M Q1'26, $2M Q2'26); a lease impairment ($4M, Q3'25).
A23: - Transformational initiatives: severance ($47M FY25) and ERP upgrade costs ($14M FY25; ERP only in 2026).
A24: - Other (Q4'25): $19M Illumina Foundation donation; FY25 also $3M board changes and $2M legal accrual.
A25: - Strategic investments: mark-to-market on holdings (mainly GRAIL stock); FY25 gain of $333M ($192M in Q4'25) excluded; Q1'26 loss $37M excluded.
A26: - Tax: Q3'25 excludes a one-time $42M valuation allowance on foreign tax credits (FY $62M); GILTI/Pillar Two (GRAIL losses) items ended in 2025.
A27: - Definition notes: 2024 shown Core vs consolidated (FY24 non-GAAP EPS $4.16 Core vs $2.45 consolidated); inventory step-up add-back new from Q1'26; deferred-comp cost sits in non-GAAP opex (~60bps of Q2'26 margin) and is offset in other income; Q1'26/Q2'26 decks dropped the net-income reconciliation (non-GAAP NI here derived).
A29: B. Commentary on consumables margins
A30: Illumina does not disclose margin by product. What is said:
A31: - MGMT (Q4'23): NovaSeq X consumables were 'designed so margins at scale would be comparable' to the 6000's; early X margins lower, normalizing through 2024.
A32: - MGMT (Aug 2024 strategy update): consumables pull-through 'drives almost 70% gross margin'; the X transition's lower pricing is 'strategically a drag'.
A33: - MGMT (Q3'24): gross margin 70.5% (+450bps), about half from consumables mix; X-transition price impact 'closer towards 25 rather than 20' (%).
... A40: C. Walk-down of $1 of revenue (FY25 reported; FY26E consensus)
A41: Line | B41: FY25 non-GAAP $M | C41: per $1 | D41: FY25 GAAP $M | E41: per $1 | F41: FY26E non-GAAP $M | G41: per $1
A42: Revenue | B42: 4343 | C42: =B42/B$42 -> 1 | D42: 4343 | E42: =D42/D$42 -> 1 | F42: 4624.8 | G42: =F42/F$42 -> 1
A43: (-) Cost of revenue | B43: -1379 | C43: =B43/B$42 -> -0.31752245 | D43: -1473 | E43: =D43/D$42 -> -0.33916647 | F43: -1464.1 | G43: =F43/F$42 -> -0.31657585
A44: GROSS PROFIT | B44: 2964 | C44: =B44/B$42 -> 0.68247755 | D44: 2870 | E44: =D44/D$42 -> 0.66083353 | F44: 3160.7 | G44: =F44/F$42 -> 0.68342415
A45: (-) R&D | B45: -950 | C45: =B45/B$42 -> -0.2187428 | D45: -967 | E45: =D45/D$42 -> -0.22265715 | F45: -984.2 | G45: =F45/F$42 -> -0.2128092
A46: (-) SG&A | B46: -1009 | C46: =B46/B$42 -> -0.23232788 | D46: -1086 | E46: =D46/D$42 -> -0.25005756 | F46: -1089.7 | G46: =F46/F$42 -> -0.235621
A47: (-) Legal contingency / other | B47: 0 | C47: =B47/B$42 -> 0 | D47: -10 | E47: =D47/D$42 -> -0.0023025558 | F47: 0 | G47: =F47/F$42 -> 0
A48: OPERATING INCOME | B48: 1004 | C48: =B48/B$42 -> 0.23117661 | D48: 807 | E48: =D48/D$42 -> 0.18581626 | F48: 1088.5 | G48: =F48/F$42 -> 0.23536153
A49: (+/-) Other income / expense, net | B49: -54 | C49: =B49/B$42 -> -0.012433802 | D49: 279 | E49: =D49/D$42 -> 0.064241308 | F49: -57.8 | G49: =F49/F$42 -> -0.012497838
A50: PRE-TAX INCOME | B50: 950 | C50: =B50/B$42 -> 0.2187428 | D50: 1086 | E50: =D50/D$42 -> 0.25005756 | F50: 1030.7 | G50: =F50/F$42 -> 0.22286369
A51: (-) Income tax | B51: -194 | C51: =B51/B$42 -> -0.044669583 | D51: -236 | E51: =D51/D$42 -> -0.054340318 | F51: -211.2 | G51: =F51/F$42 -> -0.04566684
...

Sheet Data
A1: ILMN data: inputs (blue) and formulas (black). $M unless noted. Sources: ILMN decks, 10-Q/10-K, calls; Bloomberg consensus 10 Oct 2026.
A3: Metric | B3: Row | C3: Q1'24 | D3: Q2'24 | E3: Q3'24 | F3: Q4'24 | G3: Q1'25 | H3: Q2'25 | I3: Q3'25 | J3: Q4'25 | K3: Q1'26 | L3: Q2'26 | M3: Q3'26E | N3: Q4'26E | O3: Q1'27E | P3: Q2'27E | Q3: Q3'27E | R3: Q4'27E | T3: Annual | U3: FY23 | V3: FY24 | W3: FY25 | X3: FY26E | Y3: FY27E | Z3: FY28E | AA3: FY29E | AB3: FY30E
A4: Consolidated revenue ($M) | B4: value | C4: 1056 | D4: 1092 | E4: 1080 | F4: 1104 | G4: 1041 | H4: 1059 | I4: 1084 | J4: 1159 | K4: 1091 | L4: 1159 | M4: 1154.2 | N4: 1219.8 | O4: 1159.6 | P4: 1217.8 | Q4: 1229.2 | R4: 1292.3 | U4: 4438 | V4: 4332 | W4: 4343 | X4: 4624.8 | Y4: 4918.3 | Z4: 5262.8 | AA4: 5649.7 | AB4: 6087.9 | AD4: 2024 = Core Illumina (ex-GRAIL); Q3'24/Q4'24 y/y = reported Core growth
A5: Consolidated revenue ($M) y/y | B5: yoy | C5: n/a | D5: n/a | E5: -0.02 | F5: 0.01 | G5: =IF(AND(ISNUMBER(G4),ISNUMBER(C4)),G4/C4-1,"n/a") -> -0.014204545 | H5: =IF(AND(ISNUMBER(H4),ISNUMBER(D4)),H4/D4-1,"n/a") -> -0.03021978 | I5: =IF(AND(ISNUMBER(I4),ISNUMBER(E4)),I4/E4-1,"n/a") -> 0.0037037037 | J5: =IF(AND(ISNUMBER(J4),ISNUMBER(F4)),J4/F4-1,"n/a") -> 0.049818841 | K5: =IF(AND(ISNUMBER(K4),ISNUMBER(G4)),K4/G4-1,"n/a") -> 0.04803074 | L5: =IF(AND(ISNUMBER(L4),ISNUMBER(H4)),L4/H4-1,"n/a") -> 0.094428706 | M5: =IF(AND(ISNUMBER(M4),ISNUMBER(I4)),M4/I4-1,"n/a") -> 0.064760148 | N5: =IF(AND(ISNUMBER(N4),ISNUMBER(J4)),N4/J4-1,"n/a") -> 0.052459016 | ... R5: =IF(AND(ISNUMBER(R4),ISNUMBER(N4)),R4/N4-1,"n/a") -> 0.059435973 | U5: n/a | V5: =IF(AND(ISNUMBER(V4),ISNUMBER(U4)),V4/U4-1,"n/a") -> -0.023884633 | W5: =IF(AND(ISNUMBER(W4),ISNUMBER(V4)),W4/V4-1,"n/a") -> 0.0025392428 | X5: =IF(AND(ISNUMBER(X4),ISNUMBER(W4)),X4/W4-1,"n/a") -> 0.064886023 | Y5: =IF(AND(ISNUMBER(Y4),ISNUMBER(X4)),Y4/X4-1,"n/a") -> 0.063462204 | Z5: =IF(AND(ISNUMBER(Z4),ISNUMBER(Y4)),Z4/Y4-1,"n/a") -> 0.070044528 | AA5: =IF(AND(ISNUMBER(AA4),ISNUMBER(Z4)),AA4/Z4-1,"n/a") -> 0.073515999 | AB5: =IF(AND(ISNUMBER(AB4),ISNUMBER(AA4)),AB4/AA4-1,"n/a") -> 0.07756164
A6: Consolidated revenue ($M) q/q | B6: qoq | C6: n/a | D6: =IF(AND(ISNUMBER(D4),ISNUMBER(C4)),D4/C4-1,"n/a") -> 0.034090909 | E6: =IF(AND(ISNUMBER(E4),ISNUMBER(D4)),E4/D4-1,"n/a") -> -0.010989011 | F6: =IF(AND(ISNUMBER(F4),ISNUMBER(E4)),F4/E4-1,"n/a") -> 0.022222222 | G6: =IF(AND(ISNUMBER(G4),ISNUMBER(F4)),G4/F4-1,"n/a") -> -0.057065217 | H6: =IF(AND(ISNUMBER(H4),ISNUMBER(G4)),H4/G4-1,"n/a") -> 0.017291066 | I6: =IF(AND(ISNUMBER(I4),ISNUMBER(H4)),I4/H4-1,"n/a") -> 0.023607177 | J6: =IF(AND(ISNUMBER(J4),ISNUMBER(I4)),J4/I4-1,"n/a") -> 0.069188192 | K6: =IF(AND(ISNUMBER(K4),ISNUMBER(J4)),K4/J4-1,"n/a") -> -0.058671268 | ... R6: =IF(AND(ISNUMBER(R4),ISNUMBER(Q4)),R4/Q4-1,"n/a") -> 0.051334201 | U6: n/a | V6: n/a | W6: n/a | X6: n/a | Y6: n/a | Z6: n/a | AA6: n/a | AB6: n/a
A7: Consolidated revenue ($M) 2-yr stack | B7: stk | C7: n/a | D7: n/a | E7: n/a | F7: n/a | G7: =IF(AND(ISNUMBER(G5),ISNUMBER(C5)),G5+C5,"n/a") -> n/a | H7: =IF(AND(ISNUMBER(H5),ISNUMBER(D5)),H5+D5,"n/a") -> n/a | I7: =IF(AND(ISNUMBER(I5),ISNUMBER(E5)),I5+E5,"n/a") -> -0.016296296 | J7: =IF(AND(ISNUMBER(J5),ISNUMBER(F5)),J5+F5,"n/a") -> 0.059818841 | K7: =IF(AND(ISNUMBER(K5),ISNUMBER(G5)),K5+G5,"n/a") -> 0.033826194 | L7: =IF(AND(ISNUMBER(L5),ISNUMBER(H5)),L5+H5,"n/a") -> 0.064208926 | M7: =IF(AND(ISNUMBER(M5),ISNUMBER(I5)),M5+I5,"n/a") -> 0.068463851 | N7: =IF(AND(ISNUMBER(N5),ISNUMBER(J5)),N5+J5,"n/a") -> 0.10227786 | ... R7: =IF(AND(ISNUMBER(R5),ISNUMBER(N5)),R5+N5,"n/a") -> 0.11189499 | U7: n/a | V7: n/a | W7: =IF(AND(ISNUMBER(W5),ISNUMBER(V5)),W5+V5,"n/a") -> -0.02134539 | X7: =IF(AND(ISNUMBER(X5),ISNUMBER(W5)),X5+W5,"n/a") -> 0.067425266 | Y7: =IF(AND(ISNUMBER(Y5),ISNUMBER(X5)),Y5+X5,"n/a") -> 0.12834823 | Z7: =IF(AND(ISNUMBER(Z5),ISNUMBER(Y5)),Z5+Y5,"n/a") -> 0.13350673 | AA7: =IF(AND(ISNUMBER(AA5),ISNUMBER(Z5)),AA5+Z5,"n/a") -> 0.14356053 | AB7: =IF(AND(ISNUMBER(AB5),ISNUMBER(AA5)),AB5+AA5,"n/a") -> 0.15107764
A9: Revenue ex-China ($M) | B9: value | C9: 978 | D9: 1017 | E9: 1005 | F9: 1024 | G9: 969 | H9: 996 | I9: 1032 | J9: 1104 | K9: 1039 | L9: 1103 | M9: 1103.4 | N9: 1167.9 | O9: 1115 | P9: 1170.8 | Q9: 1182.7 | R9: 1243.4 | U9: 4054 | V9: 4024 | W9: 4100 | X9: 4414.1 | Y9: 4729 | Z9: 5075.7 | AA9: 5419.8 | AB9: 5881 | AD9: Total less Greater China; estimates = consensus total less consensus Greater China
A10: Revenue ex-China ($M) y/y | B10: yoy | C10: n/a | D10: n/a | E10: n/a | F10: n/a | G10: =IF(AND(ISNUMBER(G9),ISNUMBER(C9)),G9/C9-1,"n/a") -> -0.009202454 | H10: =IF(AND(ISNUMBER(H9),ISNUMBER(D9)),H9/D9-1,"n/a") -> -0.020648968 | I10: =IF(AND(ISNUMBER(I9),ISNUMBER(E9)),I9/E9-1,"n/a") -> 0.026865672 | J10: =IF(AND(ISNUMBER(J9),ISNUMBER(F9)),J9/F9-1,"n/a") -> 0.078125 | K10: =IF(AND(ISNUMBER(K9),ISNUMBER(G9)),K9/G9-1,"n/a") -> 0.072239422 | L10: =IF(AND(ISNUMBER(L9),ISNUMBER(H9)),L9/H9-1,"n/a") -> 0.10742972 | M10: =IF(AND(ISNUMBER(M9),ISNUMBER(I9)),M9/I9-1,"n/a") -> 0.069186047 | N10: =IF(AND(ISNUMBER(N9),ISNUMBER(J9)),N9/J9-1,"n/a") -> 0.057880435 | ... R10: =IF(AND(ISNUMBER(R9),ISNUMBER(N9)),R9/N9-1,"n/a") -> 0.064645946 | U10: n/a | V10: =IF(AND(ISNUMBER(V9),ISNUMBER(U9)),V9/U9-1,"n/a") -> -0.0074000987 | W10: =IF(AND(ISNUMBER(W9),ISNUMBER(V9)),W9/V9-1,"n/a") -> 0.01888668 | X10: =IF(AND(ISNUMBER(X9),ISNUMBER(W9)),X9/W9-1,"n/a") -> 0.076609756 | Y10: =IF(AND(ISNUMBER(Y9),ISNUMBER(X9)),Y9/X9-1,"n/a") -> 0.071339571 | Z10: =IF(AND(ISNUMBER(Z9),ISNUMBER(Y9)),Z9/Y9-1,"n/a") -> 0.073313597 | AA10: =IF(AND(ISNUMBER(AA9),ISNUMBER(Z9)),AA9/Z9-1,"n/a") -> 0.067793605 | AB10: =IF(AND(ISNUMBER(AB9),ISNUMBER(AA9)),AB9/AA9-1,"n/a") -> 0.085095391
A11: Revenue ex-China ($M) q/q | B11: qoq | C11: n/a | D11: =IF(AND(ISNUMBER(D9),ISNUMBER(C9)),D9/C9-1,"n/a") -> 0.039877301 | E11: =IF(AND(ISNUMBER(E9),ISNUMBER(D9)),E9/D9-1,"n/a") -> -0.01179941 | F11: =IF(AND(ISNUMBER(F9),ISNUMBER(E9)),F9/E9-1,"n/a") -> 0.018905473 | G11: =IF(AND(ISNUMBER(G9),ISNUMBER(F9)),G9/F9-1,"n/a") -> -0.053710938 | H11: =IF(AND(ISNUMBER(H9),ISNUMBER(G9)),H9/G9-1,"n/a") -> 0.027863777 | I11: =IF(AND(ISNUMBER(I9),ISNUMBER(H9)),I9/H9-1,"n/a") -> 0.036144578 | J11: =IF(AND(ISNUMBER(J9),ISNUMBER(I9)),J9/I9-1,"n/a") -> 0.069767442 | K11: =IF(AND(ISNUMBER(K9),ISNUMBER(J9)),K9/J9-1,"n/a") -> -0.058876812 | ... R11: =IF(AND(ISNUMBER(R9),ISNUMBER(Q9)),R9/Q9-1,"n/a") -> 0.051323243 | U11: n/a | V11: n/a | W11: n/a | X11: n/a | Y11: n/a | Z11: n/a | AA11: n/a | AB11: n/a
A12: Revenue ex-China ($M) 2-yr stack | B12: stk | C12: n/a | D12: n/a | E12: n/a | F12: n/a | G12: =IF(AND(ISNUMBER(G10),ISNUMBER(C10)),G10+C10,"n/a") -> n/a | H12: =IF(AND(ISNUMBER(H10),ISNUMBER(D10)),H10+D10,"n/a") -> n/a | I12: =IF(AND(ISNUMBER(I10),ISNUMBER(E10)),I10+E10,"n/a") -> n/a | J12: =IF(AND(ISNUMBER(J10),ISNUMBER(F10)),J10+F10,"n/a") -> n/a | K12: =IF(AND(ISNUMBER(K10),ISNUMBER(G10)),K10+G10,"n/a") -> 0.063036968 | L12: =IF(AND(ISNUMBER(L10),ISNUMBER(H10)),L10+H10,"n/a") -> 0.086780751 | M12: =IF(AND(ISNUMBER(M10),ISNUMBER(I10)),M10+I10,"n/a") -> 0.096051718 | N12: =IF(AND(ISNUMBER(N10),ISNUMBER(J10)),N10+J10,"n/a") -> 0.13600543 | ... R12: =IF(AND(ISNUMBER(R10),ISNUMBER(N10)),R10+N10,"n/a") -> 0.12252638 | U12: n/a | V12: n/a | W12: =IF(AND(ISNUMBER(W10),ISNUMBER(V10)),W10+V10,"n/a") -> 0.011486581 | X12: =IF(AND(ISNUMBER(X10),ISNUMBER(W10)),X10+W10,"n/a") -> 0.095496436 | Y12: =IF(AND(ISNUMBER(Y10),ISNUMBER(X10)),Y10+X10,"n/a") -> 0.14794933 | Z12: =IF(AND(ISNUMBER(Z10),ISNUMBER(Y10)),Z10+Y10,"n/a") -> 0.14465317 | AA12: =IF(AND(ISNUMBER(AA10),ISNUMBER(Z10)),AA10+Z10,"n/a") -> 0.1411072 | AB12: =IF(AND(ISNUMBER(AB10),ISNUMBER(AA10)),AB10+AA10,"n/a") -> 0.152889
A14: NovaSeq X placements (units) | B14: value | C14: 55 | D14: 62 | E14: 58 | F14: 91 | G14: 60 | H14: 50 | I14: 55 | J14: 100 | K14: 83 | L14: 95 | M14: n/a | N14: n/a | O14: n/a | P14: n/a | Q14: n/a | R14: n/a | U14: 352 | V14: 266 | W14: 265 | X14: n/a | Y14: n/a | Z14: n/a | AA14: n/a | AB14: n/a | AD14: Disclosed as lower bounds (e.g. '55+', '100+', '95+'); no consensus
A15: NovaSeq X placements (units) y/y | B15: yoy | C15: n/a | D15: n/a | E15: -0.40206186 | F15: 0.15189873 | G15: =IF(AND(ISNUMBER(G14),ISNUMBER(C14)),G14/C14-1,"n/a") -> 0.090909091 | H15: =IF(AND(ISNUMBER(H14),ISNUMBER(D14)),H14/D14-1,"n/a") -> -0.19354839 | I15: =IF(AND(ISNUMBER(I14),ISNUMBER(E14)),I14/E14-1,"n/a") -> -0.051724138 | J15: =IF(AND(ISNUMBER(J14),ISNUMBER(F14)),J14/F14-1,"n/a") -> 0.098901099 | K15: =IF(AND(ISNUMBER(K14),ISNUMBER(G14)),K14/G14-1,"n/a") -> 0.38333333 | L15: =IF(AND(ISNUMBER(L14),ISNUMBER(H14)),L14/H14-1,"n/a") -> 0.9 | M15: =IF(AND(ISNUMBER(M14),ISNUMBER(I14)),M14/I14-1,"n/a") -> n/a | N15: =IF(AND(ISNUMBER(N14),ISNUMBER(J14)),N14/J14-1,"n/a") -> n/a | ... R15: =IF(AND(ISNUMBER(R14),ISNUMBER(N14)),R14/N14-1,"n/a") -> n/a | U15: n/a | V15: =IF(AND(ISNUMBER(V14),ISNUMBER(U14)),V14/U14-1,"n/a") -> -0.24431818 | W15: =IF(AND(ISNUMBER(W14),ISNUMBER(V14)),W14/V14-1,"n/a") -> -0.0037593985 | X15: =IF(AND(ISNUMBER(X14),ISNUMBER(W14)),X14/W14-1,"n/a") -> n/a | Y15: =IF(AND(ISNUMBER(Y14),ISNUMBER(X14)),Y14/X14-1,"n/a") -> n/a | Z15: =IF(AND(ISNUMBER(Z14),ISNUMBER(Y14)),Z14/Y14-1,"n/a") -> n/a | AA15: =IF(AND(ISNUMBER(AA14),ISNUMBER(Z14)),AA14/Z14-1,"n/a") -> n/a | AB15: =IF(AND(ISNUMBER(AB14),ISNUMBER(AA14)),AB14/AA14-1,"n/a") -> n/a
A16: NovaSeq X placements (units) q/q | B16: qoq | C16: n/a | D16: =IF(AND(ISNUMBER(D14),ISNUMBER(C14)),D14/C14-1,"n/a") -> 0.12727273 | E16: =IF(AND(ISNUMBER(E14),ISNUMBER(D14)),E14/D14-1,"n/a") -> -0.064516129 | F16: =IF(AND(ISNUMBER(F14),ISNUMBER(E14)),F14/E14-1,"n/a") -> 0.56896552 | G16: =IF(AND(ISNUMBER(G14),ISNUMBER(F14)),G14/F14-1,"n/a") -> -0.34065934 | H16: =IF(AND(ISNUMBER(H14),ISNUMBER(G14)),H14/G14-1,"n/a") -> -0.16666667 | I16: =IF(AND(ISNUMBER(I14),ISNUMBER(H14)),I14/H14-1,"n/a") -> 0.1 | J16: =IF(AND(ISNUMBER(J14),ISNUMBER(I14)),J14/I14-1,"n/a") -> 0.81818182 | K16: =IF(AND(ISNUMBER(K14),ISNUMBER(J14)),K14/J14-1,"n/a") -> -0.17 | ... R16: =IF(AND(ISNUMBER(R14),ISNUMBER(Q14)),R14/Q14-1,"n/a") -> n/a | U16: n/a | V16: n/a | W16: n/a | X16: n/a | Y16: n/a | Z16: n/a | AA16: n/a | AB16: n/a
A17: NovaSeq X placements (units) 2-yr stack | B17: stk | C17: n/a | D17: n/a | E17: n/a | F17: n/a | G17: =IF(AND(ISNUMBER(G15),ISNUMBER(C15)),G15+C15,"n/a") -> n/a | H17: =IF(AND(ISNUMBER(H15),ISNUMBER(D15)),H15+D15,"n/a") -> n/a | I17: =IF(AND(ISNUMBER(I15),ISNUMBER(E15)),I15+E15,"n/a") -> -0.45378599 | J17: =IF(AND(ISNUMBER(J15),ISNUMBER(F15)),J15+F15,"n/a") -> 0.25079983 | K17: =IF(AND(ISNUMBER(K15),ISNUMBER(G15)),K15+G15,"n/a") -> 0.47424242 | L17: =IF(AND(ISNUMBER(L15),ISNUMBER(H15)),L15+H15,"n/a") -> 0.70645161 | M17: =IF(AND(ISNUMBER(M15),ISNUMBER(I15)),M15+I15,"n/a") -> n/a | N17: =IF(AND(ISNUMBER(N15),ISNUMBER(J15)),N15+J15,"n/a") -> n/a | ... R17: =IF(AND(ISNUMBER(R15),ISNUMBER(N15)),R15+N15,"n/a") -> n/a | U17: n/a | V17: n/a | W17: =IF(AND(ISNUMBER(W15),ISNUMBER(V15)),W15+V15,"n/a") -> -0.24807758 | X17: =IF(AND(ISNUMBER(X15),ISNUMBER(W15)),X15+W15,"n/a") -> n/a | Y17: =IF(AND(ISNUMBER(Y15),ISNUMBER(X15)),Y15+X15,"n/a") -> n/a | Z17: =IF(AND(ISNUMBER(Z15),ISNUMBER(Y15)),Z15+Y15,"n/a") -> n/a | AA17: =IF(AND(ISNUMBER(AA15),ISNUMBER(Z15)),AA15+Z15,"n/a") -> n/a | AB17: =IF(AND(ISNUMBER(AB15),ISNUMBER(AA15)),AB15+AA15,"n/a") -> n/a
A19: Instruments revenue ($M) | B19: value | C19: 114 | D19: 120 | E19: 107 | F19: 159 | G19: 112 | H19: 101 | I19: 111 | J19: 158 | K19: 120 | L19: 130 | M19: 115.2 | N19: 131.5 | O19: 111.1 | P19: 114 | Q19: 111.6 | R19: 126.8 | U19: 704 | V19: 501 | W19: 482 | X19: 500.4 | Y19: 469.7 | Z19: 468.5 | AA19: 464.6 | AB19: 482.5 | AD19: Sequencing + microarray instruments
A20: Instruments revenue ($M) y/y | B20: yoy | C20: n/a | D20: n/a | E20: -0.41208791 | F20: -0.047904192 | G20: =IF(AND(ISNUMBER(G19),ISNUMBER(C19)),G19/C19-1,"n/a") -> -0.01754386 | H20: =IF(AND(ISNUMBER(H19),ISNUMBER(D19)),H19/D19-1,"n/a") -> -0.15833333 | I20: =IF(AND(ISNUMBER(I19),ISNUMBER(E19)),I19/E19-1,"n/a") -> 0.037383178 | J20: =IF(AND(ISNUMBER(J19),ISNUMBER(F19)),J19/F19-1,"n/a") -> -0.0062893082 | K20: =IF(AND(ISNUMBER(K19),ISNUMBER(G19)),K19/G19-1,"n/a") -> 0.071428571 | L20: =IF(AND(ISNUMBER(L19),ISNUMBER(H19)),L19/H19-1,"n/a") -> 0.28712871 | M20: =IF(AND(ISNUMBER(M19),ISNUMBER(I19)),M19/I19-1,"n/a") -> 0.037837838 | N20: =IF(AND(ISNUMBER(N19),ISNUMBER(J19)),N19/J19-1,"n/a") -> -0.16772152 | ... R20: =IF(AND(ISNUMBER(R19),ISNUMBER(N19)),R19/N19-1,"n/a") -> -0.035741445 | U20: n/a | V20: =IF(AND(ISNUMBER(V19),ISNUMBER(U19)),V19/U19-1,"n/a") -> -0.28835227 | W20: =IF(AND(ISNUMBER(W19),ISNUMBER(V19)),W19/V19-1,"n/a") -> -0.037924152 | X20: =IF(AND(ISNUMBER(X19),ISNUMBER(W19)),X19/W19-1,"n/a") -> 0.038174274 | Y20: =IF(AND(ISNUMBER(Y19),ISNUMBER(X19)),Y19/X19-1,"n/a") -> -0.061350919 | Z20: =IF(AND(ISNUMBER(Z19),ISNUMBER(Y19)),Z19/Y19-1,"n/a") -> -0.0025548222 | AA20: =IF(AND(ISNUMBER(AA19),ISNUMBER(Z19)),AA19/Z19-1,"n/a") -> -0.0083244397 | AB20: =IF(AND(ISNUMBER(AB19),ISNUMBER(AA19)),AB19/AA19-1,"n/a") -> 0.038527766
A21: Instruments revenue ($M) q/q | B21: qoq | C21: n/a | D21: =IF(AND(ISNUMBER(D19),ISNUMBER(C19)),D19/C19-1,"n/a") -> 0.052631579 | E21: =IF(AND(ISNUMBER(E19),ISNUMBER(D19)),E19/D19-1,"n/a") -> -0.10833333 | F21: =IF(AND(ISNUMBER(F19),ISNUMBER(E19)),F19/E19-1,"n/a") -> 0.48598131 | G21: =IF(AND(ISNUMBER(G19),ISNUMBER(F19)),G19/F19-1,"n/a") -> -0.29559748 | H21: =IF(AND(ISNUMBER(H19),ISNUMBER(G19)),H19/G19-1,"n/a") -> -0.098214286 | I21: =IF(AND(ISNUMBER(I19),ISNUMBER(H19)),I19/H19-1,"n/a") -> 0.099009901 | J21: =IF(AND(ISNUMBER(J19),ISNUMBER(I19)),J19/I19-1,"n/a") -> 0.42342342 | K21: =IF(AND(ISNUMBER(K19),ISNUMBER(J19)),K19/J19-1,"n/a") -> -0.24050633 | ... R21: =IF(AND(ISNUMBER(R19),ISNUMBER(Q19)),R19/Q19-1,"n/a") -> 0.13620072 | U21: n/a | V21: n/a | W21: n/a | X21: n/a | Y21: n/a | Z21: n/a | AA21: n/a | AB21: n/a
A22: Instruments revenue ($M) 2-yr stack | B22: stk | C22: n/a | D22: n/a | E22: n/a | F22: n/a | G22: =IF(AND(ISNUMBER(G20),ISNUMBER(C20)),G20+C20,"n/a") -> n/a | H22: =IF(AND(ISNUMBER(H20),ISNUMBER(D20)),H20+D20,"n/a") -> n/a | I22: =IF(AND(ISNUMBER(I20),ISNUMBER(E20)),I20+E20,"n/a") -> -0.37470473 | J22: =IF(AND(ISNUMBER(J20),ISNUMBER(F20)),J20+F20,"n/a") -> -0.0541935 | K22: =IF(AND(ISNUMBER(K20),ISNUMBER(G20)),K20+G20,"n/a") -> 0.053884712 | L22: =IF(AND(ISNUMBER(L20),ISNUMBER(H20)),L20+H20,"n/a") -> 0.12879538 | M22: =IF(AND(ISNUMBER(M20),ISNUMBER(I20)),M20+I20,"n/a") -> 0.075221015 | N22: =IF(AND(ISNUMBER(N20),ISNUMBER(J20)),N20+J20,"n/a") -> -0.17401083 | ... R22: =IF(AND(ISNUMBER(R20),ISNUMBER(N20)),R20+N20,"n/a") -> -0.20346296 | U22: n/a | V22: n/a | W22: =IF(AND(ISNUMBER(W20),ISNUMBER(V20)),W20+V20,"n/a") -> -0.32627642 | X22: =IF(AND(ISNUMBER(X20),ISNUMBER(W20)),X20+W20,"n/a") -> 0.00025012216 | Y22: =IF(AND(ISNUMBER(Y20),ISNUMBER(X20)),Y20+X20,"n/a") -> -0.023176645 | Z22: =IF(AND(ISNUMBER(Z20),ISNUMBER(Y20)),Z20+Y20,"n/a") -> -0.063905741 | AA22: =IF(AND(ISNUMBER(AA20),ISNUMBER(Z20)),AA20+Z20,"n/a") -> -0.010879262 | AB22: =IF(AND(ISNUMBER(AB20),ISNUMBER(AA20)),AB20+AA20,"n/a") -> 0.030203326
A24: Sequencing instruments ex-China ($M) | B24: value | C24: 100 | D24: 111 | E24: 98 | F24: 144 | G24: 103 | H24: 92 | I24: 104 | J24: 150 | K24: 114 | L24: 122 | M24: n/a | N24: n/a | O24: n/a | P24: n/a | Q24: n/a | R24: n/a | U24: n/a | V24: 453 | W24: 449 | X24: n/a | Y24: n/a | Z24: n/a | AA24: n/a | AB24: n/a | AD24: Company 'Rest of World' disclosure; no consensus by region and line
A25: Sequencing instruments ex-China ($M) y/y | B25: yoy | C25: n/a | D25: n/a | E25: n/a | F25: n/a | G25: =IF(AND(ISNUMBER(G24),ISNUMBER(C24)),G24/C24-1,"n/a") -> 0.03 | H25: =IF(AND(ISNUMBER(H24),ISNUMBER(D24)),H24/D24-1,"n/a") -> -0.17117117 | I25: =IF(AND(ISNUMBER(I24),ISNUMBER(E24)),I24/E24-1,"n/a") -> 0.06122449 | J25: =IF(AND(ISNUMBER(J24),ISNUMBER(F24)),J24/F24-1,"n/a") -> 0.041666667 | K25: =IF(AND(ISNUMBER(K24),ISNUMBER(G24)),K24/G24-1,"n/a") -> 0.10679612 | L25: =IF(AND(ISNUMBER(L24),ISNUMBER(H24)),L24/H24-1,"n/a") -> 0.32608696 | M25: =IF(AND(ISNUMBER(M24),ISNUMBER(I24)),M24/I24-1,"n/a") -> n/a | N25: =IF(AND(ISNUMBER(N24),ISNUMBER(J24)),N24/J24-1,"n/a") -> n/a | ... R25: =IF(AND(ISNUMBER(R24),ISNUMBER(N24)),R24/N24-1,"n/a") -> n/a | U25: n/a | V25: =IF(AND(ISNUMBER(V24),ISNUMBER(U24)),V24/U24-1,"n/a") -> n/a | W25: =IF(AND(ISNUMBER(W24),ISNUMBER(V24)),W24/V24-1,"n/a") -> -0.0088300221 | X25: =IF(AND(ISNUMBER(X24),ISNUMBER(W24)),X24/W24-1,"n/a") -> n/a | Y25: =IF(AND(ISNUMBER(Y24),ISNUMBER(X24)),Y24/X24-1,"n/a") -> n/a | Z25: =IF(AND(ISNUMBER(Z24),ISNUMBER(Y24)),Z24/Y24-1,"n/a") -> n/a | AA25: =IF(AND(ISNUMBER(AA24),ISNUMBER(Z24)),AA24/Z24-1,"n/a") -> n/a | AB25: =IF(AND(ISNUMBER(AB24),ISNUMBER(AA24)),AB24/AA24-1,"n/a") -> n/a
A26: Sequencing instruments ex-China ($M) q/q | B26: qoq | C26: n/a | D26: =IF(AND(ISNUMBER(D24),ISNUMBER(C24)),D24/C24-1,"n/a") -> 0.11 | E26: =IF(AND(ISNUMBER(E24),ISNUMBER(D24)),E24/D24-1,"n/a") -> -0.11711712 | F26: =IF(AND(ISNUMBER(F24),ISNUMBER(E24)),F24/E24-1,"n/a") -> 0.46938776 | G26: =IF(AND(ISNUMBER(G24),ISNUMBER(F24)),G24/F24-1,"n/a") -> -0.28472222 | H26: =IF(AND(ISNUMBER(H24),ISNUMBER(G24)),H24/G24-1,"n/a") -> -0.10679612 | I26: =IF(AND(ISNUMBER(I24),ISNUMBER(H24)),I24/H24-1,"n/a") -> 0.13043478 | J26: =IF(AND(ISNUMBER(J24),ISNUMBER(I24)),J24/I24-1,"n/a") -> 0.44230769 | K26: =IF(AND(ISNUMBER(K24),ISNUMBER(J24)),K24/J24-1,"n/a") -> -0.24 | ... R26: =IF(AND(ISNUMBER(R24),ISNUMBER(Q24)),R24/Q24-1,"n/a") -> n/a | U26: n/a | V26: n/a | W26: n/a | X26: n/a | Y26: n/a | Z26: n/a | AA26: n/a | AB26: n/a
A27: Sequencing instruments ex-China ($M) 2-yr stack | B27: stk | C27: n/a | D27: n/a | E27: n/a | F27: n/a | G27: =IF(AND(ISNUMBER(G25),ISNUMBER(C25)),G25+C25,"n/a") -> n/a | H27: =IF(AND(ISNUMBER(H25),ISNUMBER(D25)),H25+D25,"n/a") -> n/a | I27: =IF(AND(ISNUMBER(I25),ISNUMBER(E25)),I25+E25,"n/a") -> n/a | J27: =IF(AND(ISNUMBER(J25),ISNUMBER(F25)),J25+F25,"n/a") -> n/a | K27: =IF(AND(ISNUMBER(K25),ISNUMBER(G25)),K25+G25,"n/a") -> 0.13679612 | L27: =IF(AND(ISNUMBER(L25),ISNUMBER(H25)),L25+H25,"n/a") -> 0.15491579 | M27: =IF(AND(ISNUMBER(M25),ISNUMBER(I25)),M25+I25,"n/a") -> n/a | N27: =IF(AND(ISNUMBER(N25),ISNUMBER(J25)),N25+J25,"n/a") -> n/a | ... R27: =IF(AND(ISNUMBER(R25),ISNUMBER(N25)),R25+N25,"n/a") -> n/a | U27: n/a | V27: n/a | W27: =IF(AND(ISNUMBER(W25),ISNUMBER(V25)),W25+V25,"n/a") -> n/a | X27: =IF(AND(ISNUMBER(X25),ISNUMBER(W25)),X25+W25,"n/a") -> n/a | Y27: =IF(AND(ISNUMBER(Y25),ISNUMBER(X25)),Y25+X25,"n/a") -> n/a | Z27: =IF(AND(ISNUMBER(Z25),ISNUMBER(Y25)),Z25+Y25,"n/a") -> n/a | AA27: =IF(AND(ISNUMBER(AA25),ISNUMBER(Z25)),AA25+Z25,"n/a") -> n/a | AB27: =IF(AND(ISNUMBER(AB25),ISNUMBER(AA25)),AB25+AA25,"n/a") -> n/a
A29: Consumables revenue ($M) | B29: value | C29: 768 | D29: 815 | E29: 807 | F29: 779 | G29: 768 | H29: 811 | I29: 816 | J29: 832 | K29: 797 | L29: 852 | M29: 861 | N29: 894.2 | O29: 862.8 | P29: 914.1 | Q29: 931.5 | R29: 966.6 | U29: 3083 | V29: 3169 | W29: 3227 | X29: 3402.1 | Y29: 3668.6 | Z29: 3963.8 | AA29: 4341.2 | AB29: 4791.6 | AD29: Sequencing + microarray consumables
A30: Consumables revenue ($M) y/y | B30: yoy | C30: n/a | D30: n/a | E30: 0.053524804 | F30: 0.03042328 | G30: =IF(AND(ISNUMBER(G29),ISNUMBER(C29)),G29/C29-1,"n/a") -> 0 | H30: =IF(AND(ISNUMBER(H29),ISNUMBER(D29)),H29/D29-1,"n/a") -> -0.0049079755 | I30: =IF(AND(ISNUMBER(I29),ISNUMBER(E29)),I29/E29-1,"n/a") -> 0.011152416 | J30: =IF(AND(ISNUMBER(J29),ISNUMBER(F29)),J29/F29-1,"n/a") -> 0.068035944 | K30: =IF(AND(ISNUMBER(K29),ISNUMBER(G29)),K29/G29-1,"n/a") -> 0.037760417 | L30: =IF(AND(ISNUMBER(L29),ISNUMBER(H29)),L29/H29-1,"n/a") -> 0.050554871 | M30: =IF(AND(ISNUMBER(M29),ISNUMBER(I29)),M29/I29-1,"n/a") -> 0.055147059 | N30: =IF(AND(ISNUMBER(N29),ISNUMBER(J29)),N29/J29-1,"n/a") -> 0.074759615 | ... R30: =IF(AND(ISNUMBER(R29),ISNUMBER(N29)),R29/N29-1,"n/a") -> 0.080966227 | U30: n/a | V30: =IF(AND(ISNUMBER(V29),ISNUMBER(U29)),V29/U29-1,"n/a") -> 0.027894908 | W30: =IF(AND(ISNUMBER(W29),ISNUMBER(V29)),W29/V29-1,"n/a") -> 0.018302304 | X30: =IF(AND(ISNUMBER(X29),ISNUMBER(W29)),X29/W29-1,"n/a") -> 0.054260923 | Y30: =IF(AND(ISNUMBER(Y29),ISNUMBER(X29)),Y29/X29-1,"n/a") -> 0.07833397 | Z30: =IF(AND(ISNUMBER(Z29),ISNUMBER(Y29)),Z29/Y29-1,"n/a") -> 0.080466663 | AA30: =IF(AND(ISNUMBER(AA29),ISNUMBER(Z29)),AA29/Z29-1,"n/a") -> 0.095211666 | AB30: =IF(AND(ISNUMBER(AB29),ISNUMBER(AA29)),AB29/AA29-1,"n/a") -> 0.10375012
A31: Consumables revenue ($M) q/q | B31: qoq | C31: n/a | D31: =IF(AND(ISNUMBER(D29),ISNUMBER(C29)),D29/C29-1,"n/a") -> 0.061197917 | E31: =IF(AND(ISNUMBER(E29),ISNUMBER(D29)),E29/D29-1,"n/a") -> -0.0098159509 | F31: =IF(AND(ISNUMBER(F29),ISNUMBER(E29)),F29/E29-1,"n/a") -> -0.034696406 | G31: =IF(AND(ISNUMBER(G29),ISNUMBER(F29)),G29/F29-1,"n/a") -> -0.014120668 | H31: =IF(AND(ISNUMBER(H29),ISNUMBER(G29)),H29/G29-1,"n/a") -> 0.055989583 | I31: =IF(AND(ISNUMBER(I29),ISNUMBER(H29)),I29/H29-1,"n/a") -> 0.0061652281 | J31: =IF(AND(ISNUMBER(J29),ISNUMBER(I29)),J29/I29-1,"n/a") -> 0.019607843 | K31: =IF(AND(ISNUMBER(K29),ISNUMBER(J29)),K29/J29-1,"n/a") -> -0.042067308 | ... R31: =IF(AND(ISNUMBER(R29),ISNUMBER(Q29)),R29/Q29-1,"n/a") -> 0.037681159 | U31: n/a | V31: n/a | W31: n/a | X31: n/a | Y31: n/a | Z31: n/a | AA31: n/a | AB31: n/a
A32: Consumables revenue ($M) 2-yr stack | B32: stk | C32: n/a | D32: n/a | E32: n/a | F32: n/a | G32: =IF(AND(ISNUMBER(G30),ISNUMBER(C30)),G30+C30,"n/a") -> n/a | H32: =IF(AND(ISNUMBER(H30),ISNUMBER(D30)),H30+D30,"n/a") -> n/a | I32: =IF(AND(ISNUMBER(I30),ISNUMBER(E30)),I30+E30,"n/a") -> 0.064677221 | J32: =IF(AND(ISNUMBER(J30),ISNUMBER(F30)),J30+F30,"n/a") -> 0.098459224 | K32: =IF(AND(ISNUMBER(K30),ISNUMBER(G30)),K30+G30,"n/a") -> 0.037760417 | L32: =IF(AND(ISNUMBER(L30),ISNUMBER(H30)),L30+H30,"n/a") -> 0.045646895 | M32: =IF(AND(ISNUMBER(M30),ISNUMBER(I30)),M30+I30,"n/a") -> 0.066299475 | N32: =IF(AND(ISNUMBER(N30),ISNUMBER(J30)),N30+J30,"n/a") -> 0.14279556 | ... R32: =IF(AND(ISNUMBER(R30),ISNUMBER(N30)),R30+N30,"n/a") -> 0.15572584 | U32: n/a | V32: n/a | W32: =IF(AND(ISNUMBER(W30),ISNUMBER(V30)),W30+V30,"n/a") -> 0.046197211 | X32: =IF(AND(ISNUMBER(X30),ISNUMBER(W30)),X30+W30,"n/a") -> 0.072563227 | Y32: =IF(AND(ISNUMBER(Y30),ISNUMBER(X30)),Y30+X30,"n/a") -> 0.13259489 | Z32: =IF(AND(ISNUMBER(Z30),ISNUMBER(Y30)),Z30+Y30,"n/a") -> 0.15880063 | AA32: =IF(AND(ISNUMBER(AA30),ISNUMBER(Z30)),AA30+Z30,"n/a") -> 0.17567833 | AB32: =IF(AND(ISNUMBER(AB30),ISNUMBER(AA30)),AB30+AA30,"n/a") -> 0.19896178
A34: Sequencing consumables ($M) | B34: value | C34: 697 | D34: 737 | E34: 741 | F34: 698 | G34: 696 | H34: 740 | I34: 747 | J34: 755 | K34: 726 | L34: 775 | M34: 789.2 | N34: 814.9 | O34: 792.1 | P34: 838.9 | Q34: 859.8 | R34: 888.1 | U34: 2790 | V34: 2872 | W34: 2939 | X34: 3104.4 | Y34: 3378.4 | Z34: 3694.2 | AA34: 4034 | AB34: 4478.8 | AD34: Q4'24 derived from FY; Q3'23/Q4'23 from 10-Q/10-K
A35: Sequencing consumables ($M) y/y | B35: yoy | C35: n/a | D35: n/a | E35: 0.075471698 | F35: 0.023460411 | G35: =IF(AND(ISNUMBER(G34),ISNUMBER(C34)),G34/C34-1,"n/a") -> -0.0014347202 | H35: =IF(AND(ISNUMBER(H34),ISNUMBER(D34)),H34/D34-1,"n/a") -> 0.0040705563 | I35: =IF(AND(ISNUMBER(I34),ISNUMBER(E34)),I34/E34-1,"n/a") -> 0.008097166 | J35: =IF(AND(ISNUMBER(J34),ISNUMBER(F34)),J34/F34-1,"n/a") -> 0.081661891 | K35: =IF(AND(ISNUMBER(K34),ISNUMBER(G34)),K34/G34-1,"n/a") -> 0.043103448 | L35: =IF(AND(ISNUMBER(L34),ISNUMBER(H34)),L34/H34-1,"n/a") -> 0.047297297 | M35: =IF(AND(ISNUMBER(M34),ISNUMBER(I34)),M34/I34-1,"n/a") -> 0.056492637 | N35: =IF(AND(ISNUMBER(N34),ISNUMBER(J34)),N34/J34-1,"n/a") -> 0.079337748 | ... R35: =IF(AND(ISNUMBER(R34),ISNUMBER(N34)),R34/N34-1,"n/a") -> 0.089826973 | U35: n/a | V35: =IF(AND(ISNUMBER(V34),ISNUMBER(U34)),V34/U34-1,"n/a") -> 0.029390681 | W35: =IF(AND(ISNUMBER(W34),ISNUMBER(V34)),W34/V34-1,"n/a") -> 0.023328691 | X35: =IF(AND(ISNUMBER(X34),ISNUMBER(W34)),X34/W34-1,"n/a") -> 0.056277645 | Y35: =IF(AND(ISNUMBER(Y34),ISNUMBER(X34)),Y34/X34-1,"n/a") -> 0.088261822 | Z35: =IF(AND(ISNUMBER(Z34),ISNUMBER(Y34)),Z34/Y34-1,"n/a") -> 0.093476202 | AA35: =IF(AND(ISNUMBER(AA34),ISNUMBER(Z34)),AA34/Z34-1,"n/a") -> 0.091982026 | AB35: =IF(AND(ISNUMBER(AB34),ISNUMBER(AA34)),AB34/AA34-1,"n/a") -> 0.11026277
A36: Sequencing consumables ($M) q/q | B36: qoq | C36: n/a | D36: =IF(AND(ISNUMBER(D34),ISNUMBER(C34)),D34/C34-1,"n/a") -> 0.057388809 | E36: =IF(AND(ISNUMBER(E34),ISNUMBER(D34)),E34/D34-1,"n/a") -> 0.0054274084 | F36: =IF(AND(ISNUMBER(F34),ISNUMBER(E34)),F34/E34-1,"n/a") -> -0.05802969 | G36: =IF(AND(ISNUMBER(G34),ISNUMBER(F34)),G34/F34-1,"n/a") -> -0.0028653295 | H36: =IF(AND(ISNUMBER(H34),ISNUMBER(G34)),H34/G34-1,"n/a") -> 0.063218391 | I36: =IF(AND(ISNUMBER(I34),ISNUMBER(H34)),I34/H34-1,"n/a") -> 0.0094594595 | J36: =IF(AND(ISNUMBER(J34),ISNUMBER(I34)),J34/I34-1,"n/a") -> 0.010709505 | K36: =IF(AND(ISNUMBER(K34),ISNUMBER(J34)),K34/J34-1,"n/a") -> -0.038410596 | ... R36: =IF(AND(ISNUMBER(R34),ISNUMBER(Q34)),R34/Q34-1,"n/a") -> 0.032914631 | U36: n/a | V36: n/a | W36: n/a | X36: n/a | Y36: n/a | Z36: n/a | AA36: n/a | AB36: n/a
A37: Sequencing consumables ($M) 2-yr stack | B37: stk | C37: n/a | D37: n/a | E37: n/a | F37: n/a | G37: =IF(AND(ISNUMBER(G35),ISNUMBER(C35)),G35+C35,"n/a") -> n/a | H37: =IF(AND(ISNUMBER(H35),ISNUMBER(D35)),H35+D35,"n/a") -> n/a | I37: =IF(AND(ISNUMBER(I35),ISNUMBER(E35)),I35+E35,"n/a") -> 0.083568864 | J37: =IF(AND(ISNUMBER(J35),ISNUMBER(F35)),J35+F35,"n/a") -> 0.1051223 | K37: =IF(AND(ISNUMBER(K35),ISNUMBER(G35)),K35+G35,"n/a") -> 0.041668728 | L37: =IF(AND(ISNUMBER(L35),ISNUMBER(H35)),L35+H35,"n/a") -> 0.051367854 | M37: =IF(AND(ISNUMBER(M35),ISNUMBER(I35)),M35+I35,"n/a") -> 0.064589803 | N37: =IF(AND(ISNUMBER(N35),ISNUMBER(J35)),N35+J35,"n/a") -> 0.16099964 | ... R37: =IF(AND(ISNUMBER(R35),ISNUMBER(N35)),R35+N35,"n/a") -> 0.16916472 | U37: n/a | V37: n/a | W37: =IF(AND(ISNUMBER(W35),ISNUMBER(V35)),W35+V35,"n/a") -> 0.052719372 | X37: =IF(AND(ISNUMBER(X35),ISNUMBER(W35)),X35+W35,"n/a") -> 0.079606336 | Y37: =IF(AND(ISNUMBER(Y35),ISNUMBER(X35)),Y35+X35,"n/a") -> 0.14453947 | Z37: =IF(AND(ISNUMBER(Z35),ISNUMBER(Y35)),Z35+Y35,"n/a") -> 0.18173802 | AA37: =IF(AND(ISNUMBER(AA35),ISNUMBER(Z35)),AA35+Z35,"n/a") -> 0.18545823 | AB37: =IF(AND(ISNUMBER(AB35),ISNUMBER(AA35)),AB35+AA35,"n/a") -> 0.20224479
A39: Sequencing consumables ex-China ($M) | B39: value | C39: 642 | D39: 679 | E39: 684 | F39: 640 | G39: 640 | H39: 690 | I39: 707 | J39: 713 | K39: 687 | L39: 734 | M39: n/a | N39: n/a | O39: n/a | P39: n/a | Q39: n/a | R39: n/a | U39: n/a | V39: 2645 | W39: 2750 | X39: n/a | Y39: n/a | Z39: n/a | AA39: n/a | AB39: n/a | AD39: Company 'Rest of World' disclosure; FY26 guide: mid-single-digit growth
A40: Sequencing consumables ex-China ($M) y/y | B40: yoy | C40: n/a | D40: n/a | E40: 0.09 | F40: 0.02 | G40: =IF(AND(ISNUMBER(G39),ISNUMBER(C39)),G39/C39-1,"n/a") -> -0.0031152648 | H40: =IF(AND(ISNUMBER(H39),ISNUMBER(D39)),H39/D39-1,"n/a") -> 0.016200295 | I40: =IF(AND(ISNUMBER(I39),ISNUMBER(E39)),I39/E39-1,"n/a") -> 0.033625731 | J40: =IF(AND(ISNUMBER(J39),ISNUMBER(F39)),J39/F39-1,"n/a") -> 0.1140625 | K40: =IF(AND(ISNUMBER(K39),ISNUMBER(G39)),K39/G39-1,"n/a") -> 0.0734375 | L40: =IF(AND(ISNUMBER(L39),ISNUMBER(H39)),L39/H39-1,"n/a") -> 0.063768116 | M40: =IF(AND(ISNUMBER(M39),ISNUMBER(I39)),M39/I39-1,"n/a") -> n/a | N40: =IF(AND(ISNUMBER(N39),ISNUMBER(J39)),N39/J39-1,"n/a") -> n/a | ... R40: =IF(AND(ISNUMBER(R39),ISNUMBER(N39)),R39/N39-1,"n/a") -> n/a | U40: n/a | V40: 0.04 | W40: =IF(AND(ISNUMBER(W39),ISNUMBER(V39)),W39/V39-1,"n/a") -> 0.039697543 | X40: =IF(AND(ISNUMBER(X39),ISNUMBER(W39)),X39/W39-1,"n/a") -> n/a | Y40: =IF(AND(ISNUMBER(Y39),ISNUMBER(X39)),Y39/X39-1,"n/a") -> n/a | Z40: =IF(AND(ISNUMBER(Z39),ISNUMBER(Y39)),Z39/Y39-1,"n/a") -> n/a | AA40: =IF(AND(ISNUMBER(AA39),ISNUMBER(Z39)),AA39/Z39-1,"n/a") -> n/a | AB40: =IF(AND(ISNUMBER(AB39),ISNUMBER(AA39)),AB39/AA39-1,"n/a") -> n/a
A41: Sequencing consumables ex-China ($M) q/q | B41: qoq | C41: n/a | D41: =IF(AND(ISNUMBER(D39),ISNUMBER(C39)),D39/C39-1,"n/a") -> 0.057632399 | E41: =IF(AND(ISNUMBER(E39),ISNUMBER(D39)),E39/D39-1,"n/a") -> 0.0073637703 | F41: =IF(AND(ISNUMBER(F39),ISNUMBER(E39)),F39/E39-1,"n/a") -> -0.064327485 | G41: =IF(AND(ISNUMBER(G39),ISNUMBER(F39)),G39/F39-1,"n/a") -> 0 | H41: =IF(AND(ISNUMBER(H39),ISNUMBER(G39)),H39/G39-1,"n/a") -> 0.078125 | I41: =IF(AND(ISNUMBER(I39),ISNUMBER(H39)),I39/H39-1,"n/a") -> 0.024637681 | J41: =IF(AND(ISNUMBER(J39),ISNUMBER(I39)),J39/I39-1,"n/a") -> 0.0084865629 | K41: =IF(AND(ISNUMBER(K39),ISNUMBER(J39)),K39/J39-1,"n/a") -> -0.036465638 | ... R41: =IF(AND(ISNUMBER(R39),ISNUMBER(Q39)),R39/Q39-1,"n/a") -> n/a | U41: n/a | V41: n/a | W41: n/a | X41: n/a | Y41: n/a | Z41: n/a | AA41: n/a | AB41: n/a
A42: Sequencing consumables ex-China ($M) 2-yr stack | B42: stk | C42: n/a | D42: n/a | E42: n/a | F42: n/a | G42: =IF(AND(ISNUMBER(G40),ISNUMBER(C40)),G40+C40,"n/a") -> n/a | H42: =IF(AND(ISNUMBER(H40),ISNUMBER(D40)),H40+D40,"n/a") -> n/a | I42: =IF(AND(ISNUMBER(I40),ISNUMBER(E40)),I40+E40,"n/a") -> 0.12362573 | J42: =IF(AND(ISNUMBER(J40),ISNUMBER(F40)),J40+F40,"n/a") -> 0.1340625 | K42: =IF(AND(ISNUMBER(K40),ISNUMBER(G40)),K40+G40,"n/a") -> 0.070322235 | L42: =IF(AND(ISNUMBER(L40),ISNUMBER(H40)),L40+H40,"n/a") -> 0.07996841 | M42: =IF(AND(ISNUMBER(M40),ISNUMBER(I40)),M40+I40,"n/a") -> n/a | N42: =IF(AND(ISNUMBER(N40),ISNUMBER(J40)),N40+J40,"n/a") -> n/a | ... R42: =IF(AND(ISNUMBER(R40),ISNUMBER(N40)),R40+N40,"n/a") -> n/a | U42: n/a | V42: n/a | W42: =IF(AND(ISNUMBER(W40),ISNUMBER(V40)),W40+V40,"n/a") -> 0.079697543 | X42: =IF(AND(ISNUMBER(X40),ISNUMBER(W40)),X40+W40,"n/a") -> n/a | Y42: =IF(AND(ISNUMBER(Y40),ISNUMBER(X40)),Y40+X40,"n/a") -> n/a | Z42: =IF(AND(ISNUMBER(Z40),ISNUMBER(Y40)),Z40+Y40,"n/a") -> n/a | AA42: =IF(AND(ISNUMBER(AA40),ISNUMBER(Z40)),AA40+Z40,"n/a") -> n/a | AB42: =IF(AND(ISNUMBER(AB40),ISNUMBER(AA40)),AB40+AA40,"n/a") -> n/a
A44: Clinical (ex-China seq. consumables), y/y | B44: value | C44: 0.07 | D44: 0.05 | E44: 0.11 | F44: 0.08 | G44: 0.08 | H44: 0.1 | I44: 0.12 | J44: 0.2 | K44: 0.2 | L44: 0.15 | M44: n/a | N44: n/a | O44: n/a | P44: n/a | Q44: n/a | R44: n/a | U44: n/a | V44: 0.08 | W44: 0.12 | X44: 0.15 | Y44: n/a | Z44: n/a | AA44: n/a | AB44: n/a | AD44: FY26E = guide 'mid-teens' (shown as 15%); H2'26 implied ~13%
A45: Clinical (ex-China seq. consumables), y/y 2-yr stack | B45: stk | C45: n/a | D45: n/a | E45: n/a | F45: n/a | G45: =IF(AND(ISNUMBER(G44),ISNUMBER(C44)),G44+C44,"n/a") -> 0.15 | H45: =IF(AND(ISNUMBER(H44),ISNUMBER(D44)),H44+D44,"n/a") -> 0.15 | I45: =IF(AND(ISNUMBER(I44),ISNUMBER(E44)),I44+E44,"n/a") -> 0.23 | J45: =IF(AND(ISNUMBER(J44),ISNUMBER(F44)),J44+F44,"n/a") -> 0.28 | K45: =IF(AND(ISNUMBER(K44),ISNUMBER(G44)),K44+G44,"n/a") -> 0.28 | L45: =IF(AND(ISNUMBER(L44),ISNUMBER(H44)),L44+H44,"n/a") -> 0.25 | M45: =IF(AND(ISNUMBER(M44),ISNUMBER(I44)),M44+I44,"n/a") -> n/a | N45: =IF(AND(ISNUMBER(N44),ISNUMBER(J44)),N44+J44,"n/a") -> n/a | ... R45: =IF(AND(ISNUMBER(R44),ISNUMBER(N44)),R44+N44,"n/a") -> n/a | U45: n/a | V45: =IF(AND(ISNUMBER(V44),ISNUMBER(U44)),V44+U44,"n/a") -> n/a | W45: =IF(AND(ISNUMBER(W44),ISNUMBER(V44)),W44+V44,"n/a") -> 0.2 | X45: =IF(AND(ISNUMBER(X44),ISNUMBER(W44)),X44+W44,"n/a") -> 0.27 | Y45: =IF(AND(ISNUMBER(Y44),ISNUMBER(X44)),Y44+X44,"n/a") -> n/a | Z45: =IF(AND(ISNUMBER(Z44),ISNUMBER(Y44)),Z44+Y44,"n/a") -> n/a | AA45: =IF(AND(ISNUMBER(AA44),ISNUMBER(Z44)),AA44+Z44,"n/a") -> n/a | AB45: =IF(AND(ISNUMBER(AB44),ISNUMBER(AA44)),AB44+AA44,"n/a") -> n/a
A47: Research & applied (ex-China seq. consumables), y/y | B47: value | C47: -0.05 | D47: -0.03 | E47: 0.06 | F47: -0.05 | G47: -0.11 | H47: -0.09 | I47: -0.08 | J47: 0 | K47: -0.12 | L47: -0.07 | M47: n/a | N47: n/a | O47: n/a | P47: n/a | Q47: n/a | R47: n/a | U47: n/a | V47: -0.02 | W47: -0.07 | X47: -0.075 | Y47: n/a | Z47: n/a | AA47: n/a | AB47: n/a | AD47: FY26E = guide 'mid- to high-single-digit decline' (shown as -7.5%)
A48: Research & applied (ex-China seq. consumables), y/y 2-yr stack | B48: stk | C48: n/a | D48: n/a | E48: n/a | F48: n/a | G48: =IF(AND(ISNUMBER(G47),ISNUMBER(C47)),G47+C47,"n/a") -> -0.16 | H48: =IF(AND(ISNUMBER(H47),ISNUMBER(D47)),H47+D47,"n/a") -> -0.12 | I48: =IF(AND(ISNUMBER(I47),ISNUMBER(E47)),I47+E47,"n/a") -> -0.02 | J48: =IF(AND(ISNUMBER(J47),ISNUMBER(F47)),J47+F47,"n/a") -> -0.05 | K48: =IF(AND(ISNUMBER(K47),ISNUMBER(G47)),K47+G47,"n/a") -> -0.23 | L48: =IF(AND(ISNUMBER(L47),ISNUMBER(H47)),L47+H47,"n/a") -> -0.16 | M48: =IF(AND(ISNUMBER(M47),ISNUMBER(I47)),M47+I47,"n/a") -> n/a | N48: =IF(AND(ISNUMBER(N47),ISNUMBER(J47)),N47+J47,"n/a") -> n/a | ... R48: =IF(AND(ISNUMBER(R47),ISNUMBER(N47)),R47+N47,"n/a") -> n/a | U48: n/a | V48: =IF(AND(ISNUMBER(V47),ISNUMBER(U47)),V47+U47,"n/a") -> n/a | W48: =IF(AND(ISNUMBER(W47),ISNUMBER(V47)),W47+V47,"n/a") -> -0.09 | X48: =IF(AND(ISNUMBER(X47),ISNUMBER(W47)),X47+W47,"n/a") -> -0.145 | Y48: =IF(AND(ISNUMBER(Y47),ISNUMBER(X47)),Y47+X47,"n/a") -> n/a | Z48: =IF(AND(ISNUMBER(Z47),ISNUMBER(Y47)),Z47+Y47,"n/a") -> n/a | AA48: =IF(AND(ISNUMBER(AA47),ISNUMBER(Z47)),AA47+Z47,"n/a") -> n/a | AB48: =IF(AND(ISNUMBER(AB47),ISNUMBER(AA47)),AB47+AA47,"n/a") -> n/a
A50: Adj. gross profit ($M) | B50: value | C50: 708 | D50: 758 | E50: 761 | F50: 745 | G50: 702 | H50: 735 | I50: 750 | J50: 777 | K50: 744 | L50: 790 | M50: 794.6 | N50: 837.8 | O50: 797.2 | P50: 842.1 | Q50: 852.2 | R50: 891.6 | U50: n/a | V50: 2973 | W50: 2964 | X50: 3166.6 | Y50: 3396.1 | Z50: 3659.2 | AA50: 3956.5 | AB50: 4277.4 | AD50: Estimates = consensus revenue x consensus gross-margin line
A51: Adj. gross profit ($M) y/y | B51: yoy | C51: n/a | D51: n/a | E51: n/a | F51: n/a | G51: =IF(AND(ISNUMBER(G50),ISNUMBER(C50)),G50/C50-1,"n/a") -> -0.0084745763 | H51: =IF(AND(ISNUMBER(H50),ISNUMBER(D50)),H50/D50-1,"n/a") -> -0.030343008 | I51: =IF(AND(ISNUMBER(I50),ISNUMBER(E50)),I50/E50-1,"n/a") -> -0.014454665 | J51: =IF(AND(ISNUMBER(J50),ISNUMBER(F50)),J50/F50-1,"n/a") -> 0.04295302 | K51: =IF(AND(ISNUMBER(K50),ISNUMBER(G50)),K50/G50-1,"n/a") -> 0.05982906 | L51: =IF(AND(ISNUMBER(L50),ISNUMBER(H50)),L50/H50-1,"n/a") -> 0.074829932 | M51: =IF(AND(ISNUMBER(M50),ISNUMBER(I50)),M50/I50-1,"n/a") -> 0.059466667 | N51: =IF(AND(ISNUMBER(N50),ISNUMBER(J50)),N50/J50-1,"n/a") -> 0.078249678 | ... R51: =IF(AND(ISNUMBER(R50),ISNUMBER(N50)),R50/N50-1,"n/a") -> 0.064215803 | U51: n/a | V51: =IF(AND(ISNUMBER(V50),ISNUMBER(U50)),V50/U50-1,"n/a") -> n/a | W51: =IF(AND(ISNUMBER(W50),ISNUMBER(V50)),W50/V50-1,"n/a") -> -0.0030272452 | X51: =IF(AND(ISNUMBER(X50),ISNUMBER(W50)),X50/W50-1,"n/a") -> 0.068353576 | Y51: =IF(AND(ISNUMBER(Y50),ISNUMBER(X50)),Y50/X50-1,"n/a") -> 0.07247521 | Z51: =IF(AND(ISNUMBER(Z50),ISNUMBER(Y50)),Z50/Y50-1,"n/a") -> 0.077471217 | AA51: =IF(AND(ISNUMBER(AA50),ISNUMBER(Z50)),AA50/Z50-1,"n/a") -> 0.081247267 | AB51: =IF(AND(ISNUMBER(AB50),ISNUMBER(AA50)),AB50/AA50-1,"n/a") -> 0.081107039
...
